Workbook

Sheet Dashboard - EDIT
A1: SALES REPORT (AUTOMATED)
A3: Filter by month: | C3: All
A6: New service | C6: Placed & scheduled | E6: Orders taken back | G6: Service on hold | I6: Churn | K6: Net gain / loss
A7: =TEXT(SUMPRODUCT(('NEW SERVICE & RESUME REQUESTS'!$C$4:$C$995="New Service & Resume Requests")*(($C$3="All")+(MONTH('NEW SERVICE & RESUME REQUESTS'!$G$4:$G$995)=IF($C$3="July",7,IF($C$3="August",8,0))))),"0")&" · $"&TEXT(SUMPRODUCT(('NEW SERVICE & RESUME REQUESTS'!$C$4:$C$995="New Service & Resume Requests")*(($C$3="All")+(MONTH('NEW SERVICE & RESUME REQUESTS'!$G$4:$G$995)=IF($C$3="July",7,IF($C$3="August",8,0))))*'NEW SERVICE & RESUME REQUESTS'!$E$4:$E$995)/1000,"0.0")&"k" -> 141 · $29.3k | C7: =TEXT(SUM(B233:B239),"0")&" · $"&TEXT(SUM(C233:C239)/1000,"0.0")&"k" -> 7 · $1.4k | E7: =TEXT(SUM(B243:B249),"0")&" · $"&TEXT(SUM(C243:C249)/1000,"0.0")&"k" -> 8 · $1.6k | G7: =TEXT(SUM(B253:B259),"0")&" · $"&TEXT(SUM(C253:C259)/1000,"0.0")&"k" -> 7 · $1.4k | I7: =TEXT(SUMPRODUCT((CHURN!$K$2:$K$995<>"")*(($C$3="All")+(MONTH(CHURN!$K$2:$K$995)=IF($C$3="July",7,IF($C$3="August",8,0))))),"0")&" records" -> 11 records | K7: =TEXT(SUMPRODUCT(('NEW SERVICE & RESUME REQUESTS'!$C$4:$C$995="New Service & Resume Requests")*(($C$3="All")+(MONTH('NEW SERVICE & RESUME REQUESTS'!$G$4:$G$995)=IF($C$3="July",7,IF($C$3="August",8,0)))))-SUMPRODUCT((CHURN!$K$2:$K$995<>"")*(($C$3="All")+(MONTH(CHURN!$K$2:$K$995)=IF($C$3="July",7,IF($C$3="August",8,0))))),"+0;-0") -> +130
A22: By state
A72: Aged Care (New Service & Resume Requests) | B72: Already Received | C72: Targeted | D72: Value
A73: Resi | B73: =SUMPRODUCT(('NEW SERVICE & RESUME REQUESTS'!$F$4:$F$995=A73)*('NEW SERVICE & RESUME REQUESTS'!$C$4:$C$995="New Service & Resume Requests")*(($C$3="All")+(MONTH('NEW SERVICE & RESUME REQUESTS'!$G$4:$G$995)=IF($C$3="July",7,IF($C$3="August",8,0))))) -> 0 | C73: =SUMIFS(Targets!$D$5:$D$80,Targets!$A$5:$A$80,A73,Targets!$B$5:$B$80,"New Service & Resume Requests") -> 3 | D73: =SUMPRODUCT(('NEW SERVICE & RESUME REQUESTS'!$F$4:$F$995=A73)*('NEW SERVICE & RESUME REQUESTS'!$C$4:$C$995="New Service & Resume Requests")*(($C$3="All")+(MONTH('NEW SERVICE & RESUME REQUESTS'!$G$4:$G$995)=IF($C$3="July",7,IF($C$3="August",8,0))))*'NEW SERVICE & RESUME REQUESTS'!$E$4:$E$995) -> 0
A74: Silverchain VIC | B74: =SUMPRODUCT(('NEW SERVICE & RESUME REQUESTS'!$F$4:$F$995=A74)*('NEW SERVICE & RESUME REQUESTS'!$C$4:$C$995="New Service & Resume Requests")*(($C$3="All")+(MONTH('NEW SERVICE & RESUME REQUESTS'!$G$4:$G$995)=IF($C$3="July",7,IF($C$3="August",8,0))))) -> 4 | C74: =SUMIFS(Targets!$D$5:$D$80,Targets!$A$5:$A$80,A74,Targets!$B$5:$B$80,"New Service & Resume Requests") -> 29 | D74: =SUMPRODUCT(('NEW SERVICE & RESUME REQUESTS'!$F$4:$F$995=A74)*('NEW SERVICE & RESUME REQUESTS'!$C$4:$C$995="New Service & Resume Requests")*(($C$3="All")+(MONTH('NEW SERVICE & RESUME REQUESTS'!$G$4:$G$995)=IF($C$3="July",7,IF($C$3="August",8,0))))*'NEW SERVICE & RESUME REQUESTS'!$E$4:$E$995) -> 888.44
A75: Silverchain NSW | B75: =SUMPRODUCT(('NEW SERVICE & RESUME REQUESTS'!$F$4:$F$995=A75)*('NEW SERVICE & RESUME REQUESTS'!$C$4:$C$995="New Service & Resume Requests")*(($C$3="All")+(MONTH('NEW SERVICE & RESUME REQUESTS'!$G$4:$G$995)=IF($C$3="July",7,IF($C$3="August",8,0))))) -> 17 | C75: =SUMIFS(Targets!$D$5:$D$80,Targets!$A$5:$A$80,A75,Targets!$B$5:$B$80,"New Service & Resume Requests") -> 29 | D75: =SUMPRODUCT(('NEW SERVICE & RESUME REQUESTS'!$F$4:$F$995=A75)*('NEW SERVICE & RESUME REQUESTS'!$C$4:$C$995="New Service & Resume Requests")*(($C$3="All")+(MONTH('NEW SERVICE & RESUME REQUESTS'!$G$4:$G$995)=IF($C$3="July",7,IF($C$3="August",8,0))))*'NEW SERVICE & RESUME REQUESTS'!$E$4:$E$995) -> 3712.41
A76: Silverchain QLD | B76: =SUMPRODUCT(('NEW SERVICE & RESUME REQUESTS'!$F$4:$F$995=A76)*('NEW SERVICE & RESUME REQUESTS'!$C$4:$C$995="New Service & Resume Requests")*(($C$3="All")+(MONTH('NEW SERVICE & RESUME REQUESTS'!$G$4:$G$995)=IF($C$3="July",7,IF($C$3="August",8,0))))) -> 0 | C76: =SUMIFS(Targets!$D$5:$D$80,Targets!$A$5:$A$80,A76,Targets!$B$5:$B$80,"New Service & Resume Requests") -> 29 | D76: =SUMPRODUCT(('NEW SERVICE & RESUME REQUESTS'!$F$4:$F$995=A76)*('NEW SERVICE & RESUME REQUESTS'!$C$4:$C$995="New Service & Resume Requests")*(($C$3="All")+(MONTH('NEW SERVICE & RESUME REQUESTS'!$G$4:$G$995)=IF($C$3="July",7,IF($C$3="August",8,0))))*'NEW SERVICE & RESUME REQUESTS'!$E$4:$E$995) -> 0
A77: Silverchain SA | B77: =SUMPRODUCT(('NEW SERVICE & RESUME REQUESTS'!$F$4:$F$995=A77)*('NEW SERVICE & RESUME REQUESTS'!$C$4:$C$995="New Service & Resume Requests")*(($C$3="All")+(MONTH('NEW SERVICE & RESUME REQUESTS'!$G$4:$G$995)=IF($C$3="July",7,IF($C$3="August",8,0))))) -> 75 | C77: =SUMIFS(Targets!$D$5:$D$80,Targets!$A$5:$A$80,A77,Targets!$B$5:$B$80,"New Service & Resume Requests") -> 29 | D77: =SUMPRODUCT(('NEW SERVICE & RESUME REQUESTS'!$F$4:$F$995=A77)*('NEW SERVICE & RESUME REQUESTS'!$C$4:$C$995="New Service & Resume Requests")*(($C$3="All")+(MONTH('NEW SERVICE & RESUME REQUESTS'!$G$4:$G$995)=IF($C$3="July",7,IF($C$3="August",8,0))))*'NEW SERVICE & RESUME REQUESTS'!$E$4:$E$995) -> 14627.53
A78: Silverchain TAS | B78: =SUMPRODUCT(('NEW SERVICE & RESUME REQUESTS'!$F$4:$F$995=A78)*('NEW SERVICE & RESUME REQUESTS'!$C$4:$C$995="New Service & Resume Requests")*(($C$3="All")+(MONTH('NEW SERVICE & RESUME REQUESTS'!$G$4:$G$995)=IF($C$3="July",7,IF($C$3="August",8,0))))) -> 0 | C78: =SUMIFS(Targets!$D$5:$D$80,Targets!$A$5:$A$80,A78,Targets!$B$5:$B$80,"New Service & Resume Requests") -> 29 | D78: =SUMPRODUCT(('NEW SERVICE & RESUME REQUESTS'!$F$4:$F$995=A78)*('NEW SERVICE & RESUME REQUESTS'!$C$4:$C$995="New Service & Resume Requests")*(($C$3="All")+(MONTH('NEW SERVICE & RESUME REQUESTS'!$G$4:$G$995)=IF($C$3="July",7,IF($C$3="August",8,0))))*'NEW SERVICE & RESUME REQUESTS'!$E$4:$E$995) -> 0
A79: Silverchain ACT | B79: =SUMPRODUCT(('NEW SERVICE & RESUME REQUESTS'!$F$4:$F$995=A79)*('NEW SERVICE & RESUME REQUESTS'!$C$4:$C$995="New Service & Resume Requests")*(($C$3="All")+(MONTH('NEW SERVICE & RESUME REQUESTS'!$G$4:$G$995)=IF($C$3="July",7,IF($C$3="August",8,0))))) -> 14 | C79: =SUMIFS(Targets!$D$5:$D$80,Targets!$A$5:$A$80,A79,Targets!$B$5:$B$80,"New Service & Resume Requests") -> 29 | D79: =SUMPRODUCT(('NEW SERVICE & RESUME REQUESTS'!$F$4:$F$995=A79)*('NEW SERVICE & RESUME REQUESTS'!$C$4:$C$995="New Service & Resume Requests")*(($C$3="All")+(MONTH('NEW SERVICE & RESUME REQUESTS'!$G$4:$G$995)=IF($C$3="July",7,IF($C$3="August",8,0))))*'NEW SERVICE & RESUME REQUESTS'!$E$4:$E$995) -> 2719.58
A80: Blue Cross | B80: =SUMPRODUCT(('NEW SERVICE & RESUME REQUESTS'!$F$4:$F$995=A80)*('NEW SERVICE & RESUME REQUESTS'!$C$4:$C$995="New Service & Resume Requests")*(($C$3="All")+(MONTH('NEW SERVICE & RESUME REQUESTS'!$G$4:$G$995)=IF($C$3="July",7,IF($C$3="August",8,0))))) -> 0 | C80: =SUMIFS(Targets!$D$5:$D$80,Targets!$A$5:$A$80,A80,Targets!$B$5:$B$80,"New Service & Resume Requests") -> 5 | D80: =SUMPRODUCT(('NEW SERVICE & RESUME REQUESTS'!$F$4:$F$995=A80)*('NEW SERVICE & RESUME REQUESTS'!$C$4:$C$995="New Service & Resume Requests")*(($C$3="All")+(MONTH('NEW SERVICE & RESUME REQUESTS'!$G$4:$G$995)=IF($C$3="July",7,IF($C$3="August",8,0))))*'NEW SERVICE & RESUME REQUESTS'!$E$4:$E$995) -> 0
A81: Baptist Inner West/East | B81: =SUMPRODUCT(('NEW SERVICE & RESUME REQUESTS'!$F$4:$F$995=A81)*('NEW SERVICE & RESUME REQUESTS'!$C$4:$C$995="New Service & Resume Requests")*(($C$3="All")+(MONTH('NEW SERVICE & RESUME REQUESTS'!$G$4:$G$995)=IF($C$3="July",7,IF($C$3="August",8,0))))) -> 0 | C81: =SUMIFS(Targets!$D$5:$D$80,Targets!$A$5:$A$80,A81,Targets!$B$5:$B$80,"New Service & Resume Requests") -> 2 | D81: =SUMPRODUCT(('NEW SERVICE & RESUME REQUESTS'!$F$4:$F$995=A81)*('NEW SERVICE & RESUME REQUESTS'!$C$4:$C$995="New Service & Resume Requests")*(($C$3="All")+(MONTH('NEW SERVICE & RESUME REQUESTS'!$G$4:$G$995)=IF($C$3="July",7,IF($C$3="August",8,0))))*'NEW SERVICE & RESUME REQUESTS'!$E$4:$E$995) -> 0
A82: Baptist Western | B82: =SUMPRODUCT(('NEW SERVICE & RESUME REQUESTS'!$F$4:$F$995=A82)*('NEW SERVICE & RESUME REQUESTS'!$C$4:$C$995="New Service & Resume Requests")*(($C$3="All")+(MONTH('NEW SERVICE & RESUME REQUESTS'!$G$4:$G$995)=IF($C$3="July",7,IF($C$3="August",8,0))))) -> 0 | C82: =SUMIFS(Targets!$D$5:$D$80,Targets!$A$5:$A$80,A82,Targets!$B$5:$B$80,"New Service & Resume Requests") -> 2 | D82: =SUMPRODUCT(('NEW SERVICE & RESUME REQUESTS'!$F$4:$F$995=A82)*('NEW SERVICE & RESUME REQUESTS'!$C$4:$C$995="New Service & Resume Requests")*(($C$3="All")+(MONTH('NEW SERVICE & RESUME REQUESTS'!$G$4:$G$995)=IF($C$3="July",7,IF($C$3="August",8,0))))*'NEW SERVICE & RESUME REQUESTS'!$E$4:$E$995) -> 0
A83: Baptist ACT | B83: =SUMPRODUCT(('NEW SERVICE & RESUME REQUESTS'!$F$4:$F$995=A83)*('NEW SERVICE & RESUME REQUESTS'!$C$4:$C$995="New Service & Resume Requests")*(($C$3="All")+(MONTH('NEW SERVICE & RESUME REQUESTS'!$G$4:$G$995)=IF($C$3="July",7,IF($C$3="August",8,0))))) -> 0 | C83: =SUMIFS(Targets!$D$5:$D$80,Targets!$A$5:$A$80,A83,Targets!$B$5:$B$80,"New Service & Resume Requests") -> 2 | D83: =SUMPRODUCT(('NEW SERVICE & RESUME REQUESTS'!$F$4:$F$995=A83)*('NEW SERVICE & RESUME REQUESTS'!$C$4:$C$995="New Service & Resume Requests")*(($C$3="All")+(MONTH('NEW SERVICE & RESUME REQUESTS'!$G$4:$G$995)=IF($C$3="July",7,IF($C$3="August",8,0))))*'NEW SERVICE & RESUME REQUESTS'!$E$4:$E$995) -> 0
A84: Bodewell | B84: =SUMPRODUCT(('NEW SERVICE & RESUME REQUESTS'!$F$4:$F$995=A84)*('NEW SERVICE & RESUME REQUESTS'!$C$4:$C$995="New Service & Resume Requests")*(($C$3="All")+(MONTH('NEW SERVICE & RESUME REQUESTS'!$G$4:$G$995)=IF($C$3="July",7,IF($C$3="August",8,0))))) -> 0 | C84: =SUMIFS(Targets!$D$5:$D$80,Targets!$A$5:$A$80,A84,Targets!$B$5:$B$80,"New Service & Resume Requests") -> 2 | D84: =SUMPRODUCT(('NEW SERVICE & RESUME REQUESTS'!$F$4:$F$995=A84)*('NEW SERVICE & RESUME REQUESTS'!$C$4:$C$995="New Service & Resume Requests")*(($C$3="All")+(MONTH('NEW SERVICE & RESUME REQUESTS'!$G$4:$G$995)=IF($C$3="July",7,IF($C$3="August",8,0))))*'NEW SERVICE & RESUME REQUESTS'!$E$4:$E$995) -> 0
... A121: Home Aged Care Services | B121: =SUMPRODUCT(('NEW SERVICE & RESUME REQUESTS'!$F$4:$F$995=A121)*('NEW SERVICE & RESUME REQUESTS'!$C$4:$C$995="New Service & Resume Requests")*(($C$3="All")+(MONTH('NEW SERVICE & RESUME REQUESTS'!$G$4:$G$995)=IF($C$3="July",7,IF($C$3="August",8,0))))) -> 0 | C121: =SUMIFS(Targets!$D$5:$D$80,Targets!$A$5:$A$80,A121,Targets!$B$5:$B$80,"New Service & Resume Requests") -> 0 | D121: =SUMPRODUCT(('NEW SERVICE & RESUME REQUESTS'!$F$4:$F$995=A121)*('NEW SERVICE & RESUME REQUESTS'!$C$4:$C$995="New Service & Resume Requests")*(($C$3="All")+(MONTH('NEW SERVICE & RESUME REQUESTS'!$G$4:$G$995)=IF($C$3="July",7,IF($C$3="August",8,0))))*'NEW SERVICE & RESUME REQUESTS'!$E$4:$E$995) -> 0
A123: Top exit reasons (Churn / Orders Taken categories)
A124: Reason | B124: Count
A125: No reason provided | B125: =COUNTIFS(CHURN!$L$2:$L$995,"*no reason*") -> 2
A126: Moved to inhouse | B126: =COUNTIFS(CHURN!$L$2:$L$995,"*inhouse*") -> 1
A127: Discharged | B127: =COUNTIFS(CHURN!$L$2:$L$995,"*discharged*") -> 2
A128: Hospitalisation | B128: =COUNTIFS(CHURN!$L$2:$L$995,"*hospital*") -> 0
A129: Deceased | B129: =COUNTIFS(CHURN!$L$2:$L$995,"*deceased*") -> 3
A130: Changed provider | B130: =COUNTIFS(CHURN!$L$2:$L$995,"*chang*provider*") -> 0
A131: Other / not yet categorised | B131: =COUNTIFS(CHURN!$L$2:$L$995,"*")-SUM(B125:B130) -> 3
A134: New Service & Resume Requests — Client | B134: Count | C134: Total Value
A135: Australian Unity | B135: =SUMPRODUCT(('NEW SERVICE & RESUME REQUESTS'!$F$4:$F$144=A135)*(($C$3="All")+(MONTH('NEW SERVICE & RESUME REQUESTS'!$G$4:$G$144)=IF($C$3="July",7,IF($C$3="August",8,0))))) -> 9 | C135: =SUMPRODUCT(('NEW SERVICE & RESUME REQUESTS'!$F$4:$F$144=A135)*(($C$3="All")+(MONTH('NEW SERVICE & RESUME REQUESTS'!$G$4:$G$144)=IF($C$3="July",7,IF($C$3="August",8,0))))*'NEW SERVICE & RESUME REQUESTS'!$E$4:$E$144) -> 2030.72 | D135: =C135+ROW()/100000000 -> 2030.72
A136: Silverchain NSW | B136: =SUMPRODUCT(('NEW SERVICE & RESUME REQUESTS'!$F$4:$F$144=A136)*(($C$3="All")+(MONTH('NEW SERVICE & RESUME REQUESTS'!$G$4:$G$144)=IF($C$3="July",7,IF($C$3="August",8,0))))) -> 17 | C136: =SUMPRODUCT(('NEW SERVICE & RESUME REQUESTS'!$F$4:$F$144=A136)*(($C$3="All")+(MONTH('NEW SERVICE & RESUME REQUESTS'!$G$4:$G$144)=IF($C$3="July",7,IF($C$3="August",8,0))))*'NEW SERVICE & RESUME REQUESTS'!$E$4:$E$144) -> 3712.41 | D136: =C136+ROW()/100000000 -> 3712.41
A137: Calvary Syd | B137: =SUMPRODUCT(('NEW SERVICE & RESUME REQUESTS'!$F$4:$F$144=A137)*(($C$3="All")+(MONTH('NEW SERVICE & RESUME REQUESTS'!$G$4:$G$144)=IF($C$3="July",7,IF($C$3="August",8,0))))) -> 1 | C137: =SUMPRODUCT(('NEW SERVICE & RESUME REQUESTS'!$F$4:$F$144=A137)*(($C$3="All")+(MONTH('NEW SERVICE & RESUME REQUESTS'!$G$4:$G$144)=IF($C$3="July",7,IF($C$3="August",8,0))))*'NEW SERVICE & RESUME REQUESTS'!$E$4:$E$144) -> 126.92 | D137: =C137+ROW()/100000000 -> 126.92
A138: OLOC | B138: =SUMPRODUCT(('NEW SERVICE & RESUME REQUESTS'!$F$4:$F$144=A138)*(($C$3="All")+(MONTH('NEW SERVICE & RESUME REQUESTS'!$G$4:$G$144)=IF($C$3="July",7,IF($C$3="August",8,0))))) -> 1 | C138: =SUMPRODUCT(('NEW SERVICE & RESUME REQUESTS'!$F$4:$F$144=A138)*(($C$3="All")+(MONTH('NEW SERVICE & RESUME REQUESTS'!$G$4:$G$144)=IF($C$3="July",7,IF($C$3="August",8,0))))*'NEW SERVICE & RESUME REQUESTS'!$E$4:$E$144) -> 325.56 | D138: =C138+ROW()/100000000 -> 325.56
A139: Calvary Hunter | B139: =SUMPRODUCT(('NEW SERVICE & RESUME REQUESTS'!$F$4:$F$144=A139)*(($C$3="All")+(MONTH('NEW SERVICE & RESUME REQUESTS'!$G$4:$G$144)=IF($C$3="July",7,IF($C$3="August",8,0))))) -> 1 | C139: =SUMPRODUCT(('NEW SERVICE & RESUME REQUESTS'!$F$4:$F$144=A139)*(($C$3="All")+(MONTH('NEW SERVICE & RESUME REQUESTS'!$G$4:$G$144)=IF($C$3="July",7,IF($C$3="August",8,0))))*'NEW SERVICE & RESUME REQUESTS'!$E$4:$E$144) -> 95.19 | D139: =C139+ROW()/100000000 -> 95.190001
A140: Home CarIng | B140: =SUMPRODUCT(('NEW SERVICE & RESUME REQUESTS'!$F$4:$F$144=A140)*(($C$3="All")+(MONTH('NEW SERVICE & RESUME REQUESTS'!$G$4:$G$144)=IF($C$3="July",7,IF($C$3="August",8,0))))) -> 2 | C140: =SUMPRODUCT(('NEW SERVICE & RESUME REQUESTS'!$F$4:$F$144=A140)*(($C$3="All")+(MONTH('NEW SERVICE & RESUME REQUESTS'!$G$4:$G$144)=IF($C$3="July",7,IF($C$3="August",8,0))))*'NEW SERVICE & RESUME REQUESTS'!$E$4:$E$144) -> 1318.6 | D140: =C140+ROW()/100000000 -> 1318.6
A141: Silverchain ACT | B141: =SUMPRODUCT(('NEW SERVICE & RESUME REQUESTS'!$F$4:$F$144=A141)*(($C$3="All")+(MONTH('NEW SERVICE & RESUME REQUESTS'!$G$4:$G$144)=IF($C$3="July",7,IF($C$3="August",8,0))))) -> 14 | C141: =SUMPRODUCT(('NEW SERVICE & RESUME REQUESTS'!$F$4:$F$144=A141)*(($C$3="All")+(MONTH('NEW SERVICE & RESUME REQUESTS'!$G$4:$G$144)=IF($C$3="July",7,IF($C$3="August",8,0))))*'NEW SERVICE & RESUME REQUESTS'!$E$4:$E$144) -> 2719.58 | D141: =C141+ROW()/100000000 -> 2719.58
A142: Goodwin | B142: =SUMPRODUCT(('NEW SERVICE & RESUME REQUESTS'!$F$4:$F$144=A142)*(($C$3="All")+(MONTH('NEW SERVICE & RESUME REQUESTS'!$G$4:$G$144)=IF($C$3="July",7,IF($C$3="August",8,0))))) -> 4 | C142: =SUMPRODUCT(('NEW SERVICE & RESUME REQUESTS'!$F$4:$F$144=A142)*(($C$3="All")+(MONTH('NEW SERVICE & RESUME REQUESTS'!$G$4:$G$144)=IF($C$3="July",7,IF($C$3="August",8,0))))*'NEW SERVICE & RESUME REQUESTS'!$E$4:$E$144) -> 512.62 | D142: =C142+ROW()/100000000 -> 512.62
A143: Calvary Melb | B143: =SUMPRODUCT(('NEW SERVICE & RESUME REQUESTS'!$F$4:$F$144=A143)*(($C$3="All")+(MONTH('NEW SERVICE & RESUME REQUESTS'!$G$4:$G$144)=IF($C$3="July",7,IF($C$3="August",8,0))))) -> 1 | C143: =SUMPRODUCT(('NEW SERVICE & RESUME REQUESTS'!$F$4:$F$144=A143)*(($C$3="All")+(MONTH('NEW SERVICE & RESUME REQUESTS'!$G$4:$G$144)=IF($C$3="July",7,IF($C$3="August",8,0))))*'NEW SERVICE & RESUME REQUESTS'!$E$4:$E$144) -> 190.38 | D143: =C143+ROW()/100000000 -> 190.38
A144: Trilogy Care | B144: =SUMPRODUCT(('NEW SERVICE & RESUME REQUESTS'!$F$4:$F$144=A144)*(($C$3="All")+(MONTH('NEW SERVICE & RESUME REQUESTS'!$G$4:$G$144)=IF($C$3="July",7,IF($C$3="August",8,0))))) -> 1 | C144: =SUMPRODUCT(('NEW SERVICE & RESUME REQUESTS'!$F$4:$F$144=A144)*(($C$3="All")+(MONTH('NEW SERVICE & RESUME REQUESTS'!$G$4:$G$144)=IF($C$3="July",7,IF($C$3="August",8,0))))*'NEW SERVICE & RESUME REQUESTS'!$E$4:$E$144) -> 126.92 | D144: =C144+ROW()/100000000 -> 126.92
A145: Silverchain VIC | B145: =SUMPRODUCT(('NEW SERVICE & RESUME REQUESTS'!$F$4:$F$144=A145)*(($C$3="All")+(MONTH('NEW SERVICE & RESUME REQUESTS'!$G$4:$G$144)=IF($C$3="July",7,IF($C$3="August",8,0))))) -> 4 | C145: =SUMPRODUCT(('NEW SERVICE & RESUME REQUESTS'!$F$4:$F$144=A145)*(($C$3="All")+(MONTH('NEW SERVICE & RESUME REQUESTS'!$G$4:$G$144)=IF($C$3="July",7,IF($C$3="August",8,0))))*'NEW SERVICE & RESUME REQUESTS'!$E$4:$E$144) -> 888.44 | D145: =C145+ROW()/100000000 -> 888.44
...

Sheet NEW SERVICE & RESUME REQUESTS
A1: Add a new row below the table with these eight fields. State and Category use dropdown lists to prevent typos. Service Exit Date and Reason apply only to Churn and Orders Taken or Given Back records — leave blank for other categories. The Dashboard and Targets tabs update automatically — nothing else to touch.
A2: Add a new row below the table with these six fields. State and Category use dropdown lists to prevent typos. The Dashboard and Targets tabs update automatically — nothing else to touch.
A3: ID | B3: State | C3: Category | D3: Customer / Suburb | E3: Value | F3: Aged Care | G3: Date
A4: 1 | B4: NSW | C4: New Service & Resume Requests | D4: Judith Gorton - Chiswick | E4: 380.76 | F4: Australian Unity | G4: 46204
A5: 2 | B5: NSW | C5: New Service & Resume Requests | D5: Yvonne Jackson - Belmont | E5: 190.38 | F5: Australian Unity | G5: 46205
A6: 3 | B6: NSW | C6: New Service & Resume Requests | D6: Elaine Kastelan - Blacktown | E6: 253.84 | F6: Silverchain NSW | G6: 46205
A7: 4 | B7: NSW | C7: New Service & Resume Requests | D7: Con Batalis - Blacktown | E7: 190.38 | F7: Silverchain NSW | G7: 46205
A8: 5 | B8: NSW | C8: New Service & Resume Requests | D8: Jean Abrecrombie - Elermore Vale | E8: 190.38 | F8: Silverchain NSW | G8: 46206
A9: 6 | B9: NSW | C9: New Service & Resume Requests | D9: Grace O'reilly - Waratah West | E9: 190.38 | F9: Australian Unity | G9: 46206
A10: 7 | B10: NSW | C10: New Service & Resume Requests | D10: Marie Curteis - Waratah | E10: 190.38 | F10: Australian Unity | G10: 46206
A11: 8 | B11: NSW | C11: New Service & Resume Requests | D11: Jean Abrecrombie-Elermore Vale | E11: 190.38 | F11: Australian Unity | G11: 46206
A12: 9 | B12: NSW | C12: New Service & Resume Requests | D12: Valeriana Rodricks - Ingleburn | E12: 253.84 | F12: Silverchain NSW | G12: 46207
A13: 10 | B13: NSW | C13: New Service & Resume Requests | D13: Denis John Cooper - BRADBURY, | E13: 190.38 | F13: Silverchain NSW | G13: 46208
A14: 11 | B14: NSW | C14: New Service & Resume Requests | D14: Jacqueline Rose Moulston - Toongabie | E14: 253.84 | F14: Silverchain NSW | G14: 46208
A15: 12 | B15: NSW | C15: New Service & Resume Requests | D15: Angelita Zafra - Belmont North | E15: 253.84 | F15: Australian Unity | G15: 46208
... A144: 141 | B144: South Australia | C144: New Service & Resume Requests | D144: Maria Belperio - Holden Hill | E144: 190.38 | F144: Silverchain SA | G144: 46265

Sheet PLACED & SCHEDULED ORDERS
A1: ID | B1: State | C1: Category | D1: Customer / Suburb | E1: Value | F1: Aged Care | G1: Date
A2: 1 | B2: NSW | C2: Placed & Scheduled Orders | D2: Alan Whitfield - Penrith | E2: 253.84 | F2: Silverchain NSW | G2: 46206
A3: 2 | B3: VIC | C3: Placed & Scheduled Orders | D3: Colleen Baxter - Frankston | E3: 190.38 | F3: Calvary Melb | G3: 46211
A4: 3 | B4: QLD | C4: Placed & Scheduled Orders | D4: Graham Petersen - Ipswich | E4: 253.84 | F4: Bolton Clarke | G4: 46217
A5: 4 | B5: South Australia | C5: Placed & Scheduled Orders | D5: Nadia Kowalski - Elizabeth | E5: 190.38 | F5: Silverchain SA | G5: 46222
A6: 5 | B6: ACT | C6: Placed & Scheduled Orders | D6: Peter Loukas - Belconnen | E6: 126.92 | F6: Silverchain ACT | G6: 46228
A7: 6 | B7: NSW | C7: Placed & Scheduled Orders | D7: Wendy Sargent - Liverpool | E7: 380.76 | F7: Australian Unity | G7: 46236
A8: 7 | B8: VIC | C8: Placed & Scheduled Orders | D8: Ian Faulkner - Dandenong | E8: 253.84 | F8: GEN U | G8: 46243
A9: 8 | B9: QLD | C9: Placed & Scheduled Orders | D9: Rosemary Tran - Logan | E9: 190.38 | F9: Trilogy Care | G9: 46249
A10: 9 | B10: NSW | C10: Placed & Scheduled Orders | D10: Barry Nicholson - Campbelltown | E10: 253.84 | F10: Calvary Syd | G10: 46255
A11: 10 | B11: ACT | C11: Placed & Scheduled Orders | D11: Fiona Reardon - Gungahlin | E11: 190.38 | F11: Goodwin | G11: 46262

Sheet ORDERS TAKEN OR GIVEN BACK
A1: ID | B1: State | C1: Category | D1: Customer / Suburb | E1: Value | F1: Aged Care | G1: Date
A2: 1 | B2: NSW | C2: Orders Taken or Given Back | D2: Denise Marlow - Hornsby | E2: 190.38 | F2: Silverchain NSW | G2: 46207
A3: 2 | B3: VIC | C3: Orders Taken or Given Back | D3: Trevor Bianchi - Werribee | E3: 253.84 | F3: Calvary Melb | G3: 46213
A4: 3 | B4: South Australia | C4: Orders Taken or Given Back | D4: Yvette Sorensen - Salisbury | E4: 126.92 | F4: Silverchain SA | G4: 46219
A5: 4 | B5: QLD | C5: Orders Taken or Given Back | D5: Malcolm Chege - Redbank | E5: 190.38 | F5: Bolton Clarke | G5: 46225
A6: 5 | B6: ACT | C6: Orders Taken or Given Back | D6: Anthea Rowlands - Weston | E6: 253.84 | F6: Silverchain ACT | G6: 46230
A7: 6 | B7: NSW | C7: Orders Taken or Given Back | D7: Owen Kavanagh - Fairfield | E7: 190.38 | F7: Australian Unity | G7: 46237
A8: 7 | B8: VIC | C8: Orders Taken or Given Back | D8: Priya Deshpande - Sunshine | E8: 253.84 | F8: GEN U | G8: 46245
A9: 8 | B9: QLD | C9: Orders Taken or Given Back | D9: Clive Bannister - Beenleigh | E9: 126.92 | F9: Trilogy Care | G9: 46251
A10: 9 | B10: South Australia | C10: Orders Taken or Given Back | D10: Josephine Radich - Modbury | E10: 190.38 | F10: Calvary South Australia | G10: 46257
A11: 10 | B11: ACT | C11: Orders Taken or Given Back | D11: Marcus Delaney - Kambah | E11: 253.84 | F11: Goodwin | G11: 46264

Sheet CHURN
A1: DetectedDate | B1: Internal Record # | C1: FirstName | D1: LastName | E1: IsActive | F1: DateOfBirth | G1: ClientTypes | H1: PrimaryPhone | I1: Email | J1: Address | K1: ServiceExitDate | L1: ServiceExitReason | M1: Groups
A2: 46215 | B2: 7010 | C2: Trevor | D2: Simmons | E2: =FALSE() -> FALSE | F2: 15924 | G2: Ongoing | H2: 0424 887 331 | I2: t.simmons@example.com.au | J2: 10 Eucalypt Rd, Brisbane QLD | K2: 46027 | L2: Order Taken Back - Discharged | M2: GEN U
A3: 46198 | B3: 7009 | C3: Noeleen | D3: Baxter | E3: =FALSE() -> FALSE | F3: 14533 | G3: Ongoing | H3: 0478 552 664 | I3: n.baxter@example.com.au | J3: 22 Waratah Cres, Shepparton VIC | K3: 46075 | L3: Churn - No Longer Required Service | M3: Calvary Shepparton
A4: 46181 | B4: 7008 | C4: Raymond | D4: Hughes | E4: =FALSE() -> FALSE | F4: 12136 | G4: Ongoing | H4: 0466 331 209 | I4: r.hughes@example.com.au | J4: 39 Casuarina Way, Adelaide SA | K4: 46092 | L4: Churn - Deceased | M4: Silverchain SA
A5: 46163 | B5: 7007 | C5: Shirley | D5: Adams | E5: =FALSE() -> FALSE | F5: 15522 | G5: New - Once Off | H5: 0413 774 502 | I5: s.adams@example.com.au | J5: 5 Acacia Pl, Canberra ACT | K5: 46118 | L5: Order Taken Back - No reason provided | M5: Silverchain ACT
A6: 46144 | B6: 7006 | C6: Desmond | D6: Carter | E6: =FALSE() -> FALSE | F6: 13860 | G6: Ongoing | H6: 0499 213 887 | I6: d.carter@example.com.au | J6: 16 Melaleuca St, Newcastle NSW | K6: 46132 | L6: Churn - No reason provided | M6: Calvary Hunter
A7: 46127 | B7: 7005 | C7: Patricia | D7: Wallace | E7: =FALSE() -> FALSE | F7: 14645 | G7: Ongoing | H7: 0407 662 918 | I7: p.wallace@example.com.au | J7: 27 Bottlebrush Dr, Ballarat VIC | K7: 46151 | L7: Churn - Moved to inhouse | M7: Bolton Clarke
A8: 46111 | B8: 7004 | C8: Kenneth | D8: O'Brien | E8: =FALSE() -> FALSE | F8: 16334 | G8: Ongoing | H8: 0455 221 340 | I8: k.obrien@example.com.au | J8: 3 Grevillea Ave, Wollongong NSW | K8: 46170 | L8: Churn - No Longer Required Service | M8: Australian Unity
A9: 46090 | B9: 7003 | C9: Beryl | D9: Nguyen | E9: =FALSE() -> FALSE | F9: 12992 | G9: New - Once Off | H9: 0421 998 112 | I9: b.nguyen@example.com.au | J9: 8 Hakea Ct, Toowoomba QLD | K9: 46187 | L9: Order Taken Back - Deceased | M9: Calvary Syd
A10: 46071 | B10: 7002 | C10: Harold | D10: Fitzgerald | E10: =FALSE() -> FALSE | F10: 15282 | G10: Ongoing | H10: 0433 556 789 | I10: h.fitzgerald@example.com.au | J10: 45 Banksia Rd, Geelong VIC | K10: 46204 | L10: Order Taken Back - Discharged | M10: Silverchain VIC
A11: 46025 | B11: 7001 | C11: Margaret | D11: Thompson | E11: =FALSE() -> FALSE | F11: 14014 | G11: Ongoing | H11: 0412 334 221 | I11: m.thompson@example.com.au | J11: 12 Wattle St, Parramatta NSW | K11: 46222 | L11: Churn - Deceased | M11: Silverchain NSW
A12: 26/08/2026 | B12: 6185 | C12: DUMMY ACCOUNT TEST - 2 | D12: By Sarah | E12: Active | G12: New - Once Off | K12: 46335 | L12: Churn - No Longer Required Service | M12: Home Aged Care Services, TEST By Sarah Alliance Group

Sheet SERVICE ON HOLD
A1: ID | B1: State | C1: Category | D1: Customer / Suburb | E1: Value | F1: Aged Care | G1: Date
A2: 1 | B2: NSW | C2: Service On Hold | D2: Rita Chalmers - Blacktown | E2: 190.38 | F2: Silverchain NSW | G2: 46208
A3: 2 | B3: VIC | C3: Service On Hold | D3: Bruce McAllister - Geelong | E3: 253.84 | F3: Calvary Melb | G3: 46215
A4: 3 | B4: South Australia | C4: Service On Hold | D4: Helena Papadopoulos - Prospect | E4: 126.92 | F4: Silverchain SA | G4: 46221
A5: 4 | B5: QLD | C5: Service On Hold | D5: Vince Okafor - Springfield | E5: 190.38 | F5: Bolton Clarke | G5: 46227
A6: 5 | B6: ACT | C6: Service On Hold | D6: Cheryl Marsh - Tuggeranong | E6: 253.84 | F6: Silverchain ACT | G6: 46232
A7: 6 | B7: NSW | C7: Service On Hold | D7: Douglas Fenwick - Ryde | E7: 190.38 | F7: Australian Unity | G7: 46238
A8: 7 | B8: VIC | C8: Service On Hold | D8: Simone Castellano - St Kilda | E8: 253.84 | F8: GEN U | G8: 46246
A9: 8 | B9: QLD | C9: Service On Hold | D9: Errol Bamford - Caboolture | E9: 126.92 | F9: Trilogy Care | G9: 46252
A10: 9 | B10: NSW | C10: Service On Hold | D10: Adele Fairweather - Hurstville | E10: 190.38 | F10: Calvary Syd | G10: 46258
A11: 10 | B11: ACT | C11: Service On Hold | D11: Nigel Ashcroft - Kaleen | E11: 190.38 | F11: Goodwin | G11: 46265

Sheet Targets
A1: Client / funder targets — "New Service & Resume Requests"
A2: "Already Received" is a live formula counting rows in Data, matched on both client and category. "Targeted" and "Forecast" are business inputs (blue text) set by account management — edit these directly when goals change. Additional category blocks (Churn, Orders Taken or Given Back) are appended below using the same pattern — copy a block and relabel it to add a future service category.
A4: Client / Funder | B4: Category | C4: Already Received | D4: Targeted (Account-Based) | E4: Forecast | F4: Gap to Forecast | G4: % of Target Achieved | H4: Clarify (Targeted and Forecast)
A5: Resi | B5: New Service & Resume Requests | C5: =COUNTIFS('NEW SERVICE & RESUME REQUESTS'!$F$4:$F$995,A5,'NEW SERVICE & RESUME REQUESTS'!$C$4:$C$995,B5) -> 0 | D5: 3 | E5: 1 | F5: =E5-C5 -> 1 | G5: =IFERROR(C5/D5,0) -> 0
A6: Silverchain VIC | B6: New Service & Resume Requests | C6: =COUNTIFS('NEW SERVICE & RESUME REQUESTS'!$F$4:$F$995,A6,'NEW SERVICE & RESUME REQUESTS'!$C$4:$C$995,B6) -> 4 | D6: 29 | E6: 10 | F6: =E6-C6 -> 6 | G6: =IFERROR(C6/D6,0) -> 0.13793103
A7: Silverchain NSW | B7: New Service & Resume Requests | C7: =COUNTIFS('NEW SERVICE & RESUME REQUESTS'!$F$4:$F$995,A7,'NEW SERVICE & RESUME REQUESTS'!$C$4:$C$995,B7) -> 17 | D7: 29 | E7: 20 | F7: =E7-C7 -> 3 | G7: =IFERROR(C7/D7,0) -> 0.5862069
A8: Silverchain QLD | B8: New Service & Resume Requests | C8: =COUNTIFS('NEW SERVICE & RESUME REQUESTS'!$F$4:$F$995,A8,'NEW SERVICE & RESUME REQUESTS'!$C$4:$C$995,B8) -> 0 | D8: 29 | E8: 0 | F8: =E8-C8 -> 0 | G8: =IFERROR(C8/D8,0) -> 0
A9: Silverchain SA | B9: New Service & Resume Requests | C9: =COUNTIFS('NEW SERVICE & RESUME REQUESTS'!$F$4:$F$995,A9,'NEW SERVICE & RESUME REQUESTS'!$C$4:$C$995,B9) -> 75 | D9: 29 | E9: 80 | F9: =E9-C9 -> 5 | G9: =IFERROR(C9/D9,0) -> 2.5862069
A10: Silverchain TAS | B10: New Service & Resume Requests | C10: =COUNTIFS('NEW SERVICE & RESUME REQUESTS'!$F$4:$F$995,A10,'NEW SERVICE & RESUME REQUESTS'!$C$4:$C$995,B10) -> 0 | D10: 29 | E10: 0 | F10: =E10-C10 -> 0 | G10: =IFERROR(C10/D10,0) -> 0
A11: Silverchain ACT | B11: New Service & Resume Requests | C11: =COUNTIFS('NEW SERVICE & RESUME REQUESTS'!$F$4:$F$995,A11,'NEW SERVICE & RESUME REQUESTS'!$C$4:$C$995,B11) -> 14 | D11: 29 | E11: 20 | F11: =E11-C11 -> 6 | G11: =IFERROR(C11/D11,0) -> 0.48275862
A12: Blue Cross | B12: New Service & Resume Requests | C12: =COUNTIFS('NEW SERVICE & RESUME REQUESTS'!$F$4:$F$995,A12,'NEW SERVICE & RESUME REQUESTS'!$C$4:$C$995,B12) -> 0 | D12: 5 | E12: 0 | F12: =E12-C12 -> 0 | G12: =IFERROR(C12/D12,0) -> 0
A13: Baptist Inner West/East | B13: New Service & Resume Requests | C13: =COUNTIFS('NEW SERVICE & RESUME REQUESTS'!$F$4:$F$995,A13,'NEW SERVICE & RESUME REQUESTS'!$C$4:$C$995,B13) -> 0 | D13: 2 | E13: 0 | F13: =E13-C13 -> 0 | G13: =IFERROR(C13/D13,0) -> 0
A14: Baptist Western | B14: New Service & Resume Requests | C14: =COUNTIFS('NEW SERVICE & RESUME REQUESTS'!$F$4:$F$995,A14,'NEW SERVICE & RESUME REQUESTS'!$C$4:$C$995,B14) -> 0 | D14: 2 | E14: 0 | F14: =E14-C14 -> 0 | G14: =IFERROR(C14/D14,0) -> 0
A15: Baptist ACT | B15: New Service & Resume Requests | C15: =COUNTIFS('NEW SERVICE & RESUME REQUESTS'!$F$4:$F$995,A15,'NEW SERVICE & RESUME REQUESTS'!$C$4:$C$995,B15) -> 0 | D15: 2 | E15: 2 | F15: =E15-C15 -> 2 | G15: =IFERROR(C15/D15,0) -> 0
A16: Bodewell | B16: New Service & Resume Requests | C16: =COUNTIFS('NEW SERVICE & RESUME REQUESTS'!$F$4:$F$995,A16,'NEW SERVICE & RESUME REQUESTS'!$C$4:$C$995,B16) -> 0 | D16: 2 | E16: 0 | F16: =E16-C16 -> 0 | G16: =IFERROR(C16/D16,0) -> 0
... A53: Home Aged Care Services | B53: New Service & Resume Requests | C53: =COUNTIFS('NEW SERVICE & RESUME REQUESTS'!$F$4:$F$995,A53,'NEW SERVICE & RESUME REQUESTS'!$C$4:$C$995,B53) -> 0 | D53: 0 | E53: 1 | F53: =E53-C53 -> 1 | G53: =IFERROR(C53/D53,0) -> 0
A54: Other / Not Yet in Target List | B54: New Service & Resume Requests | C54: =COUNTIFS('NEW SERVICE & RESUME REQUESTS'!$C$4:$C$995,"New Service & Resume Requests")-SUM(C5:C53) -> 2 | D54: 0 | E54: 0 | F54: =E54-C54 -> -2 | G54: =IFERROR(C54/D54,0) -> 0
A55: New Service & Resume Requests Total | C55: =SUM(C5:C54) -> 141 | D55: =SUM(D5:D54) -> 348 | E55: =SUM(E5:E54) -> 195 | F55: =SUM(F5:F54) -> 54 | G55: =IFERROR(C55/D55,0) -> 0.40517241
A57: Churn
A58: Goodwin | B58: Churn | C58: =COUNTIFS(CHURN!$M$2:$M$995,A58,CHURN!$L$2:$L$995,"Churn -*") -> 0 | D58: 0 | E58: 0 | F58: =E58-C58 -> 0 | G58: =IFERROR(C58/D58,0) -> 0
A59: Australian Unity | B59: Churn | C59: =COUNTIFS(CHURN!$M$2:$M$995,A59,CHURN!$L$2:$L$995,"Churn -*") -> 1 | D59: 0 | E59: 0 | F59: =E59-C59 -> -1 | G59: =IFERROR(C59/D59,0) -> 0
A60: Other / Not Yet in Target List | B60: Churn | C60: =COUNTIFS(CHURN!$L$2:$L$995,"Churn -*")-SUM(C58:C59) -> 6 | D60: 0 | E60: 0 | F60: =E60-C60 -> -6 | G60: =IFERROR(C60/D60,0) -> 0
A61: Churn Total | C61: =SUM(C58:C60) -> 7 | D61: =SUM(D58:D60) -> 0 | E61: =SUM(E58:E60) -> 0 | F61: =SUM(F58:F60) -> -7 | G61: =IFERROR(C61/D61,0) -> 0
A63: Orders Taken or Given Back
A64: Australian Unity | B64: Orders Taken or Given Back | C64: =COUNTIFS(CHURN!$M$2:$M$995,A64,CHURN!$L$2:$L$995,"Order Taken Back -*") -> 0 | D64: 0 | E64: 0 | F64: =E64-C64 -> 0 | G64: =IFERROR(C64/D64,0) -> 0
A65: Other / Not Yet in Target List | B65: Orders Taken or Given Back | C65: =COUNTIFS(CHURN!$L$2:$L$995,"Order Taken Back -*")-SUM(C64:C64) -> 4 | D65: 0 | E65: 0 | F65: =E65-C65 -> -4 | G65: =IFERROR(C65/D65,0) -> 0
A66: Orders Taken or Given Back Total | C66: =SUM(C64:C65) -> 4 | D66: =SUM(D64:D65) -> 0 | E66: =SUM(E64:E65) -> 0 | F66: =SUM(F64:F65) -> -4 | G66: =IFERROR(C66/D66,0) -> 0
A68: Placed & Scheduled Orders
A69: Other / Not Yet in Target List | B69: Placed & Scheduled Orders | C69: =COUNTIFS('PLACED & SCHEDULED ORDERS'!$C$2:$C$995,"Placed & Scheduled Orders") -> 10 | D69: 0 | E69: 0 | F69: =E69-C69 -> -10 | G69: =IFERROR(C69/D69,0) -> 0
A70: Placed & Scheduled Orders Total | C70: =SUM(C69:C69) -> 10 | D70: =SUM(D69:D69) -> 0 | E70: =SUM(E69:E69) -> 0 | F70: =SUM(F69:F69) -> -10 | G70: =IFERROR(C70/D70,0) -> 0
A72: Service On Hold
A73: Other / Not Yet in Target List | B73: Service On Hold | C73: =COUNTIFS('SERVICE ON HOLD'!$C$2:$C$995,"Service On Hold") -> 10 | D73: 0 | E73: 0 | F73: =E73-C73 -> -10 | G73: =IFERROR(C73/D73,0) -> 0
A74: Service On Hold Total | C74: =SUM(C73:C73) -> 10 | D74: =SUM(D73:D73) -> 0 | E74: =SUM(E73:E73) -> 0 | F74: =SUM(F73:F73) -> -10 | G74: =IFERROR(C74/D74,0) -> 0
